Workbook

Sheet Template_import_matherial
A1: ID | B1: Material | C1: Model | D1: Unit type | E1: SalesArea | F1: Sale office | G1: Catologue Yes/Not | H1: Nota Descritiva | I1: Note Aggiuntive | J1: Min Q.tà | K1: Area | L1: Avviament1 | M1: Accessori | N1: Famiglia | O1: Tipologia | P1: Tecnologia | Q1: catalogo | R1: dimensionali | S1: Scheda Tecnica
D2: INT/EXT | E2: HN|RN,CN | F2: ABI0,ABI1, ... | L2: EE22, TT76 | M2: Z34,X53,S12 | U2: Seperatore:|
A9: Riga che arriva da SAP attraverso MATMAS
A10: ID | B10: Material | C10: Model | D10: Unit type | E10: SalesArea | F10: Sale office | G10: Catologue Yes/Not | H10: Nota Descritiva | I10: Note Aggiuntive | J10: Min Q.tà | K10: Area | L10: Avviament1 | M10: Accessori | N10: Famiglia | O10: Tipologia | P10: Tecnologia | Q10: catalogo | R10: dimensionali | S10: Scheda Tecnica
A11: last+1 | G11: No
O12: Deve essere possibile vedere le righe entrate da MATMAS e non trattate
O13: Considero righe con Sales area o Sales office vuoto
O14: Per queste righe, all'import dfei file di disponibilità non vengono generate righe aggiuntive
O15: la priorità per le righe inserite da matmas è l'ultima + 1

Sheet Matrice Visualizzazione File 1
B1: Filtro esposto | C1: Filtro esposto | D1: Filtro esposto | E1: Filtro esposto | H1: Esposti limitati in base al profilo utente | Q1: Esposti limitati in base al profilo utente | R1: Filtro | U1: Filtro
H2: Filtro -agente: vede solo prodotti disponibili nei sales office da ZZ_SALES_RES -operatori: tutto - area manager: solo sales office legati ai propri agenti in sales area HN + HD + CN | R2: Aggiungerte alla riga dati
A3: matherial | B3: matherial | C3: matherial | D3: matherial
A4: Ordine | B4: ID | C4: Descizione | D4: int/ext | H4: Linea 1 | I4: MRV | J4: A2W | K4: HEC | L4: ENERGY | M4: Retail | N4: ROE | O4: Service | P4: Water Heater | Q4: Se yes => è pubblico | V4: Digitare Codice | W4: Non Toccare | X4: Digitare Codice | Y4: Non Toccare | Z4: Digitare Codice | AA4: Non Toccare | AB4: Digitare Codice | AC4: Non Toccare | AD4: Digitare Codice | AE4: Non Toccare | AF4: Digitare Codice | AG4: Non Toccare | AH4: Digitare Codice | AI4: Non Toccare | AJ4: Dati Filtri / Capitolato
A5: ID | B5: Material | C5: Model | D5: Unit type | E5: HN | F5: RN | G5: CN | H5: Sale office 1 | I5: Sale Office 2 | J5: Sale office 3 | K5: Sale office 4 | L5: Sale office 5 | M5: Sale office 6 | N5: Sale office 7 | O5: Sale office 8 | P5: Sale office 9 | Q5: InCatalog | R5: Nota Descritiva | S5: Note Aggiuntive | T5: Min Q.tà | U5: Area | V5: Codice Avviamento 1 | W5: Codice Avviamento Descrizione 1 | X5: Codice Avviamento 2 | Y5: Codice Avviamento Descrizione 2 | Z5: Accessorio 1 | AA5: Accessorio Descrizione 1 | AB5: Accessorio 2 | AC5: Accessorio Descrizione 2 | AD5: Accessorio 3 | AE5: Accessorio Descrizione 3 | AF5: Accessorio 4 | AG5: Accessorio Descrizione 4 | AH5: Accessorio 5 | AI5: Accessorio Descrizione 5 | AJ5: Famiglia | AK5: Tipologia | AL5: Tecnologia | AM5: Catalogo | AN5: Dimensionali | AO5: Scheda Tecnica | AP5: Descrizione Capitolato | AQ5: Descrizione Capitolato Opzionale
A6: 1 | B6: AB97Y0E00 | C6: AP71DFMHRA DIZUN | D6: IU | E6: HN | F6: RN | H6: ABI0 | N6: AGIR | O6: ASI0 | Q6: Yes | R6: Cabinet | T6: 5 | U6: Catologue | W6: =IFERROR(VLOOKUP(V:V,$B:$C,2,),"") | Y6: =IFERROR(VLOOKUP(X:X,$B:$C,2,),"") | AA6: =IFERROR(VLOOKUP(Z:Z,$B:$C,2,),"") | AC6: =IFERROR(VLOOKUP(AB:AB,$B:$C,2,),"") | AE6: =IFERROR(VLOOKUP(AD:AD,$B:$C,2,),"") | AG6: =IFERROR(VLOOKUP(AF:AF,$B:$C,2,),"") | AI6: =IFERROR(VLOOKUP(AH:AH,$B:$C,2,),"")
A7: =A6+1 -> 2 | B7: AACKF0E00 | C7: 1U71WEMFRA DIZUN | D7: OU | E7: HN | F7: RN | H7: ABI0 | N7: AGIR | O7: ASI0 | Q7: Yes | R7: Cabinet | T7: 5 | U7: Catologue | W7: =IFERROR(VLOOKUP(V:V,$B:$C,2,),"") | Y7: =IFERROR(VLOOKUP(X:X,$B:$C,2,),"") | AA7: =IFERROR(VLOOKUP(Z:Z,$B:$C,2,),"") | AC7: =IFERROR(VLOOKUP(AB:AB,$B:$C,2,),"") | AE7: =IFERROR(VLOOKUP(AD:AD,$B:$C,2,),"") | AG7: =IFERROR(VLOOKUP(AF:AF,$B:$C,2,),"") | AI7: =IFERROR(VLOOKUP(AH:AH,$B:$C,2,),"")
A8: =A7+1 -> 3 | E8: --- | F8: --- | W8: =IFERROR(VLOOKUP(V:V,$B:$C,2,),"") | Y8: =IFERROR(VLOOKUP(X:X,$B:$C,2,),"") | AA8: =IFERROR(VLOOKUP(Z:Z,$B:$C,2,),"") | AC8: =IFERROR(VLOOKUP(AB:AB,$B:$C,2,),"") | AE8: =IFERROR(VLOOKUP(AD:AD,$B:$C,2,),"") | AG8: =IFERROR(VLOOKUP(AF:AF,$B:$C,2,),"") | AI8: =IFERROR(VLOOKUP(AH:AH,$B:$C,2,),"")
A9: =A8+1 -> 4 | B9: AAC160E00 | D9: IU | E9: HN | F9: RN | H9: ABI0 | N9: AGIR | O9: ASI0 | Q9: Yes | R9: Expert Nordic | T9: 5 | U9: Catologue | W9: =IFERROR(VLOOKUP(V:V,$B:$C,2,),"") | Y9: =IFERROR(VLOOKUP(X:X,$B:$C,2,),"") | AA9: =IFERROR(VLOOKUP(Z:Z,$B:$C,2,),"") | AC9: =IFERROR(VLOOKUP(AB:AB,$B:$C,2,),"") | AE9: =IFERROR(VLOOKUP(AD:AD,$B:$C,2,),"") | AG9: =IFERROR(VLOOKUP(AF:AF,$B:$C,2,),"") | AI9: =IFERROR(VLOOKUP(AH:AH,$B:$C,2,),"")
A10: =A9+1 -> 5 | B10: AAC180E00 | C10: 1U25KEHFRA-NR | D10: OU | E10: HN | F10: RN | H10: ABI0 | N10: AGIR | O10: ASI0 | Q10: Yes | R10: Expert Nordic | T10: 5 | U10: Catologue | W10: =IFERROR(VLOOKUP(V:V,$B:$C,2,),"") | Y10: =IFERROR(VLOOKUP(X:X,$B:$C,2,),"") | AA10: =IFERROR(VLOOKUP(Z:Z,$B:$C,2,),"") | AC10: =IFERROR(VLOOKUP(AB:AB,$B:$C,2,),"") | AE10: =IFERROR(VLOOKUP(AD:AD,$B:$C,2,),"") | AG10: =IFERROR(VLOOKUP(AF:AF,$B:$C,2,),"") | AI10: =IFERROR(VLOOKUP(AH:AH,$B:$C,2,),"")
A11: =A10+1 -> 6 | B11: AAC170E00 | C11: AS35XCHHRA-NR | D11: IU | E11: HN | F11: RN | H11: ABI0 | N11: AGIR | O11: ASI0 | Q11: Yes | R11: Expert Nordic | T11: 5 | U11: Catologue | W11: =IFERROR(VLOOKUP(V:V,$B:$C,2,),"") | Y11: =IFERROR(VLOOKUP(X:X,$B:$C,2,),"") | AA11: =IFERROR(VLOOKUP(Z:Z,$B:$C,2,),"") | AC11: =IFERROR(VLOOKUP(AB:AB,$B:$C,2,),"") | AE11: =IFERROR(VLOOKUP(AD:AD,$B:$C,2,),"") | AG11: =IFERROR(VLOOKUP(AF:AF,$B:$C,2,),"") | AI11: =IFERROR(VLOOKUP(AH:AH,$B:$C,2,),"")
A12: =A11+1 -> 7 | B12: AAC190E00 | C12: 1U35KEHFRA-NR | D12: OU | E12: HN | F12: RN | H12: ABI0 | N12: AGIR | O12: ASI0 | Q12: Yes | R12: Expert Nordic | T12: 5 | U12: Catologue | W12: =IFERROR(VLOOKUP(V:V,$B:$C,2,),"") | Y12: =IFERROR(VLOOKUP(X:X,$B:$C,2,),"") | AA12: =IFERROR(VLOOKUP(Z:Z,$B:$C,2,),"") | AC12: =IFERROR(VLOOKUP(AB:AB,$B:$C,2,),"") | AE12: =IFERROR(VLOOKUP(AD:AD,$B:$C,2,),"") | AG12: =IFERROR(VLOOKUP(AF:AF,$B:$C,2,),"") | AI12: =IFERROR(VLOOKUP(AH:AH,$B:$C,2,),"")
A13: =A12+1 -> 8 | B13: AABQN6E00 | C13: 1U35MEHFRA-1 | D13: OU | F13: RN | N13: AGIR | O13: ASI0 | Q13: Yes | R13: Flexis Nordic | T13: 5 | U13: Catologue | W13: =IFERROR(VLOOKUP(V:V,$B:$C,2,),"") | Y13: =IFERROR(VLOOKUP(X:X,$B:$C,2,),"") | AA13: =IFERROR(VLOOKUP(Z:Z,$B:$C,2,),"") | AC13: =IFERROR(VLOOKUP(AB:AB,$B:$C,2,),"") | AE13: =IFERROR(VLOOKUP(AD:AD,$B:$C,2,),"") | AG13: =IFERROR(VLOOKUP(AF:AF,$B:$C,2,),"") | AI13: =IFERROR(VLOOKUP(AH:AH,$B:$C,2,),"")
A14: =A13+1 -> 9 | B14: AAC152E00 | C14: 1U50KEFFRA-1 | D14: OU | F14: RN | N14: AGIR | O14: ASI0 | Q14: Yes | R14: Flexis Nordic | T14: 5 | U14: Catologue | W14: =IFERROR(VLOOKUP(V:V,$B:$C,2,),"") | Y14: =IFERROR(VLOOKUP(X:X,$B:$C,2,),"") | AA14: =IFERROR(VLOOKUP(Z:Z,$B:$C,2,),"") | AC14: =IFERROR(VLOOKUP(AB:AB,$B:$C,2,),"") | AE14: =IFERROR(VLOOKUP(AD:AD,$B:$C,2,),"") | AG14: =IFERROR(VLOOKUP(AF:AF,$B:$C,2,),"") | AI14: =IFERROR(VLOOKUP(AH:AH,$B:$C,2,),"")
A15: =A14+1 -> 10 | E15: --- | F15: --- | W15: =IFERROR(VLOOKUP(V:V,$B:$C,2,),"") | Y15: =IFERROR(VLOOKUP(X:X,$B:$C,2,),"") | AA15: =IFERROR(VLOOKUP(Z:Z,$B:$C,2,),"") | AC15: =IFERROR(VLOOKUP(AB:AB,$B:$C,2,),"") | AE15: =IFERROR(VLOOKUP(AD:AD,$B:$C,2,),"") | AG15: =IFERROR(VLOOKUP(AF:AF,$B:$C,2,),"") | AI15: =IFERROR(VLOOKUP(AH:AH,$B:$C,2,),"")
A16: =A15+1 -> 11 | B16: AACCP0E00 | C16: AS25PCHHRA-NR | D16: IU | F16: RN | N16: AGIR | O16: ASI0 | Q16: Yes | R16: Pearl Nordic | T16: 5 | U16: Catologue | W16: =IFERROR(VLOOKUP(V:V,$B:$C,2,),"") | Y16: =IFERROR(VLOOKUP(X:X,$B:$C,2,),"") | AA16: =IFERROR(VLOOKUP(Z:Z,$B:$C,2,),"") | AC16: =IFERROR(VLOOKUP(AB:AB,$B:$C,2,),"") | AE16: =IFERROR(VLOOKUP(AD:AD,$B:$C,2,),"") | AG16: =IFERROR(VLOOKUP(AF:AF,$B:$C,2,),"") | AI16: =IFERROR(VLOOKUP(AH:AH,$B:$C,2,),"")
A17: =A16+1 -> 12 | B17: AACCQ0E00 | C17: AS35PCHHRA-NR | D17: IU | F17: RN | N17: AGIR | O17: ASI0 | Q17: Yes | R17: Pearl Nordic | T17: 5 | U17: Catologue | W17: =IFERROR(VLOOKUP(V:V,$B:$C,2,),"") | Y17: =IFERROR(VLOOKUP(X:X,$B:$C,2,),"") | AA17: =IFERROR(VLOOKUP(Z:Z,$B:$C,2,),"") | AC17: =IFERROR(VLOOKUP(AB:AB,$B:$C,2,),"") | AE17: =IFERROR(VLOOKUP(AD:AD,$B:$C,2,),"") | AG17: =IFERROR(VLOOKUP(AF:AF,$B:$C,2,),"") | AI17: =IFERROR(VLOOKUP(AH:AH,$B:$C,2,),"")
A18: =A17+1 -> 13 | B18: AACCR0E00 | C18: AS50PDHHRA-NR | D18: IU | F18: RN | N18: AGIR | O18: ASI0 | Q18: Yes | R18: Pearl Nordic | T18: 5 | U18: Catologue | W18: =IFERROR(VLOOKUP(V:V,$B:$C,2,),"") | Y18: =IFERROR(VLOOKUP(X:X,$B:$C,2,),"") | AA18: =IFERROR(VLOOKUP(Z:Z,$B:$C,2,),"") | AC18: =IFERROR(VLOOKUP(AB:AB,$B:$C,2,),"") | AE18: =IFERROR(VLOOKUP(AD:AD,$B:$C,2,),"") | AG18: =IFERROR(VLOOKUP(AF:AF,$B:$C,2,),"") | AI18: =IFERROR(VLOOKUP(AH:AH,$B:$C,2,),"")
A19: =A18+1 -> 14 | B19: AACCS0E00 | C19: 1U25KEFFRA-NR | D19: OU | F19: RN | N19: AGIR | O19: ASI0 | Q19: Yes | R19: Pearl Nordic | T19: 5 | U19: Catologue | W19: =IFERROR(VLOOKUP(V:V,$B:$C,2,),"") | Y19: =IFERROR(VLOOKUP(X:X,$B:$C,2,),"") | AA19: =IFERROR(VLOOKUP(Z:Z,$B:$C,2,),"") | AC19: =IFERROR(VLOOKUP(AB:AB,$B:$C,2,),"") | AE19: =IFERROR(VLOOKUP(AD:AD,$B:$C,2,),"") | AG19: =IFERROR(VLOOKUP(AF:AF,$B:$C,2,),"") | AI19: =IFERROR(VLOOKUP(AH:AH,$B:$C,2,),"")
A20: =A19+1 -> 15 | B20: AACCT0E00 | C20: 1U35KEFFRA-NR | D20: OU | F20: RN | N20: AGIR | O20: ASI0 | Q20: Yes | R20: Pearl Nordic | T20: 5 | U20: Catologue | W20: =IFERROR(VLOOKUP(V:V,$B:$C,2,),"") | Y20: =IFERROR(VLOOKUP(X:X,$B:$C,2,),"") | AA20: =IFERROR(VLOOKUP(Z:Z,$B:$C,2,),"") | AC20: =IFERROR(VLOOKUP(AB:AB,$B:$C,2,),"") | AE20: =IFERROR(VLOOKUP(AD:AD,$B:$C,2,),"") | AG20: =IFERROR(VLOOKUP(AF:AF,$B:$C,2,),"") | AI20: =IFERROR(VLOOKUP(AH:AH,$B:$C,2,),"")
A21: =A20+1 -> 16 | B21: AACCU0E00 | C21: 1U50WEFFRA-NR | D21: OU | F21: RN | N21: AGIR | O21: ASI0 | Q21: Yes | R21: Pearl Nordic | T21: 5 | U21: Catologue | W21: =IFERROR(VLOOKUP(V:V,$B:$C,2,),"") | Y21: =IFERROR(VLOOKUP(X:X,$B:$C,2,),"") | AA21: =IFERROR(VLOOKUP(Z:Z,$B:$C,2,),"") | AC21: =IFERROR(VLOOKUP(AB:AB,$B:$C,2,),"") | AE21: =IFERROR(VLOOKUP(AD:AD,$B:$C,2,),"") | AG21: =IFERROR(VLOOKUP(AF:AF,$B:$C,2,),"") | AI21: =IFERROR(VLOOKUP(AH:AH,$B:$C,2,),"")
A22: =A21+1 -> 17 | E22: --- | F22: --- | W22: =IFERROR(VLOOKUP(V:V,$B:$C,2,),"") | Y22: =IFERROR(VLOOKUP(X:X,$B:$C,2,),"") | AA22: =IFERROR(VLOOKUP(Z:Z,$B:$C,2,),"") | AC22: =IFERROR(VLOOKUP(AB:AB,$B:$C,2,),"") | AE22: =IFERROR(VLOOKUP(AD:AD,$B:$C,2,),"") | AG22: =IFERROR(VLOOKUP(AF:AF,$B:$C,2,),"") | AI22: =IFERROR(VLOOKUP(AH:AH,$B:$C,2,),"")
A23: =A22+1 -> 18 | B23: AAC110E00 | C23: AS25PBBHRA | D23: IU | F23: RN | N23: AGIR | O23: ASI0 | Q23: Yes | R23: Pearl R290 | T23: 5 | U23: Catologue | W23: =IFERROR(VLOOKUP(V:V,$B:$C,2,),"") | Y23: =IFERROR(VLOOKUP(X:X,$B:$C,2,),"") | AA23: =IFERROR(VLOOKUP(Z:Z,$B:$C,2,),"") | AC23: =IFERROR(VLOOKUP(AB:AB,$B:$C,2,),"") | AE23: =IFERROR(VLOOKUP(AD:AD,$B:$C,2,),"") | AG23: =IFERROR(VLOOKUP(AF:AF,$B:$C,2,),"") | AI23: =IFERROR(VLOOKUP(AH:AH,$B:$C,2,),"")
A24: =A23+1 -> 19 | B24: AAC120E00 | C24: 1U25YEBGRA | D24: OU | F24: RN | N24: AGIR | O24: ASI0 | Q24: Yes | R24: Pearl R290 | T24: 5 | U24: Catologue | W24: =IFERROR(VLOOKUP(V:V,$B:$C,2,),"") | Y24: =IFERROR(VLOOKUP(X:X,$B:$C,2,),"") | AA24: =IFERROR(VLOOKUP(Z:Z,$B:$C,2,),"") | AC24: =IFERROR(VLOOKUP(AB:AB,$B:$C,2,),"") | AE24: =IFERROR(VLOOKUP(AD:AD,$B:$C,2,),"") | AG24: =IFERROR(VLOOKUP(AF:AF,$B:$C,2,),"") | AI24: =IFERROR(VLOOKUP(AH:AH,$B:$C,2,),"")
A25: =A24+1 -> 20 | B25: AAC130E00 | C25: AS35PBBHRA | D25: IU | F25: RN | N25: AGIR | O25: ASI0 | Q25: Yes | R25: Pearl R290 | T25: 5 | U25: Catologue | W25: =IFERROR(VLOOKUP(V:V,$B:$C,2,),"") | Y25: =IFERROR(VLOOKUP(X:X,$B:$C,2,),"") | AA25: =IFERROR(VLOOKUP(Z:Z,$B:$C,2,),"") | AC25: =IFERROR(VLOOKUP(AB:AB,$B:$C,2,),"") | AE25: =IFERROR(VLOOKUP(AD:AD,$B:$C,2,),"") | AG25: =IFERROR(VLOOKUP(AF:AF,$B:$C,2,),"") | AI25: =IFERROR(VLOOKUP(AH:AH,$B:$C,2,),"")
A26: =A25+1 -> 21 | B26: AAC140E00 | C26: 1U35YEBGRA | D26: OU | F26: RN | N26: AGIR | O26: ASI0 | Q26: Yes | R26: Pearl R290 | T26: 5 | U26: Catologue | W26: =IFERROR(VLOOKUP(V:V,$B:$C,2,),"") | Y26: =IFERROR(VLOOKUP(X:X,$B:$C,2,),"") | AA26: =IFERROR(VLOOKUP(Z:Z,$B:$C,2,),"") | AC26: =IFERROR(VLOOKUP(AB:AB,$B:$C,2,),"") | AE26: =IFERROR(VLOOKUP(AD:AD,$B:$C,2,),"") | AG26: =IFERROR(VLOOKUP(AF:AF,$B:$C,2,),"") | AI26: =IFERROR(VLOOKUP(AH:AH,$B:$C,2,),"")
A27: =A26+1 -> 22 | E27: --- | F27: --- | W27: =IFERROR(VLOOKUP(V:V,$B:$C,2,),"") | Y27: =IFERROR(VLOOKUP(X:X,$B:$C,2,),"") | AA27: =IFERROR(VLOOKUP(Z:Z,$B:$C,2,),"") | AC27: =IFERROR(VLOOKUP(AB:AB,$B:$C,2,),"") | AE27: =IFERROR(VLOOKUP(AD:AD,$B:$C,2,),"") | AG27: =IFERROR(VLOOKUP(AF:AF,$B:$C,2,),"") | AI27: =IFERROR(VLOOKUP(AH:AH,$B:$C,2,),"")
A28: =A27+1 -> 23 | B28: AABQM0E00 | C28: 1U25S2SM1FA-2 | D28: OU | E28: HN | F28: RN | H28: ABI0 | N28: AGIR | O28: ASI0 | Q28: Yes | R28: Mono SM+ | T28: 30 | U28: Catologue | W28: =IFERROR(VLOOKUP(V:V,$B:$C,2,),"") | Y28: =IFERROR(VLOOKUP(X:X,$B:$C,2,),"") | AA28: =IFERROR(VLOOKUP(Z:Z,$B:$C,2,),"") | AC28: =IFERROR(VLOOKUP(AB:AB,$B:$C,2,),"") | AE28: =IFERROR(VLOOKUP(AD:AD,$B:$C,2,),"") | AG28: =IFERROR(VLOOKUP(AF:AF,$B:$C,2,),"") | AI28: =IFERROR(VLOOKUP(AH:AH,$B:$C,2,),"")
A29: =A28+1 -> 24 | B29: AABQN0E00 | C29: 1U35S2SM1FA-2 | D29: OU | E29: HN | F29: RN | H29: ABI0 | N29: AGIR | O29: ASI0 | Q29: Yes | R29: Mono SM+ | T29: 30 | U29: Catologue | W29: =IFERROR(VLOOKUP(V:V,$B:$C,2,),"") | Y29: =IFERROR(VLOOKUP(X:X,$B:$C,2,),"") | AA29: =IFERROR(VLOOKUP(Z:Z,$B:$C,2,),"") | AC29: =IFERROR(VLOOKUP(AB:AB,$B:$C,2,),"") | AE29: =IFERROR(VLOOKUP(AD:AD,$B:$C,2,),"") | AG29: =IFERROR(VLOOKUP(AF:AF,$B:$C,2,),"") | AI29: =IFERROR(VLOOKUP(AH:AH,$B:$C,2,),"")
A30: =A29+1 -> 25 | B30: AAAYV0E09 | C30: 1U42S2SM1FA | D30: OU | E30: HN | F30: RN | H30: ABI0 | N30: AGIR | O30: ASI0 | Q30: Yes | R30: Mono SM+ | T30: 30 | U30: Catologue | W30: =IFERROR(VLOOKUP(V:V,$B:$C,2,),"") | Y30: =IFERROR(VLOOKUP(X:X,$B:$C,2,),"") | AA30: =IFERROR(VLOOKUP(Z:Z,$B:$C,2,),"") | AC30: =IFERROR(VLOOKUP(AB:AB,$B:$C,2,),"") | AE30: =IFERROR(VLOOKUP(AD:AD,$B:$C,2,),"") | AG30: =IFERROR(VLOOKUP(AF:AF,$B:$C,2,),"") | AI30: =IFERROR(VLOOKUP(AH:AH,$B:$C,2,),"")
A31: =A30+1 -> 26 | B31: AAC150E00 | C31: 1U50S2SJ2FA-2 | D31: OU | E31: HN | F31: RN | H31: ABI0 | M31: ACI0 | N31: AGIR | O31: ASI0 | Q31: Yes | R31: Mono SM+ | T31: 30 | U31: Catologue | W31: =IFERROR(VLOOKUP(V:V,$B:$C,2,),"") | Y31: =IFERROR(VLOOKUP(X:X,$B:$C,2,),"") | AA31: =IFERROR(VLOOKUP(Z:Z,$B:$C,2,),"") | AC31: =IFERROR(VLOOKUP(AB:AB,$B:$C,2,),"") | AE31: =IFERROR(VLOOKUP(AD:AD,$B:$C,2,),"") | AG31: =IFERROR(VLOOKUP(AF:AF,$B:$C,2,),"") | AI31: =IFERROR(VLOOKUP(AH:AH,$B:$C,2,),"")
A32: =A31+1 -> 27 | B32: AA9ZH1E2J | C32: 1U71S2SR2FA | D32: OU | E32: HN | F32: RN | H32: ABI0 | N32: AGIR | O32: ASI0 | Q32: No | R32: Mono SM+ | S32: Phase Out - ESAUIRTO | T32: 10 | U32: Catologue | W32: =IFERROR(VLOOKUP(V:V,$B:$C,2,),"") | Y32: =IFERROR(VLOOKUP(X:X,$B:$C,2,),"") | AA32: =IFERROR(VLOOKUP(Z:Z,$B:$C,2,),"") | AC32: =IFERROR(VLOOKUP(AB:AB,$B:$C,2,),"") | AE32: =IFERROR(VLOOKUP(AD:AD,$B:$C,2,),"") | AG32: =IFERROR(VLOOKUP(AF:AF,$B:$C,2,),"") | AI32: =IFERROR(VLOOKUP(AH:AH,$B:$C,2,),"")
A33: =A32+1 -> 28 | B33: AE1XY1E00 | C33: 1U71S2ST1FA | D33: OU | E33: HN | F33: RN | H33: ABI0 | N33: AGIR | O33: ASI0 | Q33: Yes | R33: Mono SM+ | S33: Sostituisce 1U71S2SR2FA | T33: 10 | U33: Catologue | W33: =IFERROR(VLOOKUP(V:V,$B:$C,2,),"") | Y33: =IFERROR(VLOOKUP(X:X,$B:$C,2,),"") | AA33: =IFERROR(VLOOKUP(Z:Z,$B:$C,2,),"") | AC33: =IFERROR(VLOOKUP(AB:AB,$B:$C,2,),"") | AE33: =IFERROR(VLOOKUP(AD:AD,$B:$C,2,),"") | AG33: =IFERROR(VLOOKUP(AF:AF,$B:$C,2,),"") | AI33: =IFERROR(VLOOKUP(AH:AH,$B:$C,2,),"")
A34: =A33+1 -> 29 | B34: AA9Z27E00 | C34: 1U105S2SS2FA | D34: OU | E34: HN | F34: RN | H34: ABI0 | N34: AGIR | O34: ASI0 | Q34: No | R34: Mono SM+ | S34: Phase Out - ESAUIRTO | T34: 5 | U34: LCAC | W34: =IFERROR(VLOOKUP(V:V,$B:$C,2,),"") | Y34: =IFERROR(VLOOKUP(X:X,$B:$C,2,),"") | AA34: =IFERROR(VLOOKUP(Z:Z,$B:$C,2,),"") | AC34: =IFERROR(VLOOKUP(AB:AB,$B:$C,2,),"") | AE34: =IFERROR(VLOOKUP(AD:AD,$B:$C,2,),"") | AG34: =IFERROR(VLOOKUP(AF:AF,$B:$C,2,),"") | AI34: =IFERROR(VLOOKUP(AH:AH,$B:$C,2,),"")
A35: =A34+1 -> 30 | B35: AE1XF6E00 | C35: 1U105S2SQ1FA | D35: OU | E35: HN | F35: RN | H35: ABI0 | N35: AGIR | O35: ASI0 | Q35: Yes | R35: Mono SM+ | S35: Sostituisce 1U105S2SS2FA | T35: 5 | U35: LCAC | W35: =IFERROR(VLOOKUP(V:V,$B:$C,2,),"") | Y35: =IFERROR(VLOOKUP(X:X,$B:$C,2,),"") | AA35: =IFERROR(VLOOKUP(Z:Z,$B:$C,2,),"") | AC35: =IFERROR(VLOOKUP(AB:AB,$B:$C,2,),"") | AE35: =IFERROR(VLOOKUP(AD:AD,$B:$C,2,),"") | AG35: =IFERROR(VLOOKUP(AF:AF,$B:$C,2,),"") | AI35: =IFERROR(VLOOKUP(AH:AH,$B:$C,2,),"")
A36: =A35+1 -> 31 | B36: AA9ZJ0E29 | C36: 1U105S2SS1FB | D36: OU | E36: HN | F36: RN | H36: ABI0 | N36: AGIR | O36: ASI0 | Q36: Yes | R36: Mono SM+ | S36: Three Phase | T36: 5 | U36: LCAC | W36: =IFERROR(VLOOKUP(V:V,$B:$C,2,),"") | Y36: =IFERROR(VLOOKUP(X:X,$B:$C,2,),"") | AA36: =IFERROR(VLOOKUP(Z:Z,$B:$C,2,),"") | AC36: =IFERROR(VLOOKUP(AB:AB,$B:$C,2,),"") | AE36: =IFERROR(VLOOKUP(AD:AD,$B:$C,2,),"") | AG36: =IFERROR(VLOOKUP(AF:AF,$B:$C,2,),"") | AI36: =IFERROR(VLOOKUP(AH:AH,$B:$C,2,),"")
A37: =A36+1 -> 32 | B37: AA9Z35E00 | C37: 1U125S2SN2FA | D37: OU | E37: HN | F37: RN | H37: ABI0 | N37: AGIR | O37: ASI0 | Q37: No | R37: Mono SM+ | S37: ESAUIRTO | T37: 5 | U37: LCAC | W37: =IFERROR(VLOOKUP(V:V,$B:$C,2,),"") | Y37: =IFERROR(VLOOKUP(X:X,$B:$C,2,),"") | AA37: =IFERROR(VLOOKUP(Z:Z,$B:$C,2,),"") | AC37: =IFERROR(VLOOKUP(AB:AB,$B:$C,2,),"") | AE37: =IFERROR(VLOOKUP(AD:AD,$B:$C,2,),"") | AG37: =IFERROR(VLOOKUP(AF:AF,$B:$C,2,),"") | AI37: =IFERROR(VLOOKUP(AH:AH,$B:$C,2,),"")
A38: =A37+1 -> 33 | B38: AE2182E00 | C38: 1U125S2SN3FA | D38: OU | E38: HN | F38: RN | H38: ABI0 | N38: AGIR | O38: ASI0 | Q38: Yes | R38: Mono SM+ | S38: Sostituisce 1U125S2SN2FA | T38: 5 | U38: LCAC | W38: =IFERROR(VLOOKUP(V:V,$B:$C,2,),"") | Y38: =IFERROR(VLOOKUP(X:X,$B:$C,2,),"") | AA38: =IFERROR(VLOOKUP(Z:Z,$B:$C,2,),"") | AC38: =IFERROR(VLOOKUP(AB:AB,$B:$C,2,),"") | AE38: =IFERROR(VLOOKUP(AD:AD,$B:$C,2,),"") | AG38: =IFERROR(VLOOKUP(AF:AF,$B:$C,2,),"") | AI38: =IFERROR(VLOOKUP(AH:AH,$B:$C,2,),"")
A39: =A38+1 -> 34 | B39: AA9Z38E00 | C39: 1U125S2SN2FB | D39: OU | E39: HN | F39: RN | H39: ABI0 | N39: AGIR | O39: ASI0 | Q39: Yes | R39: Mono SM+ | S39: Three Phase | T39: 5 | U39: LCAC | W39: =IFERROR(VLOOKUP(V:V,$B:$C,2,),"") | Y39: =IFERROR(VLOOKUP(X:X,$B:$C,2,),"") | AA39: =IFERROR(VLOOKUP(Z:Z,$B:$C,2,),"") | AC39: =IFERROR(VLOOKUP(AB:AB,$B:$C,2,),"") | AE39: =IFERROR(VLOOKUP(AD:AD,$B:$C,2,),"") | AG39: =IFERROR(VLOOKUP(AF:AF,$B:$C,2,),"") | AI39: =IFERROR(VLOOKUP(AH:AH,$B:$C,2,),"")
A40: =A39+1 -> 35 | B40: AE2181E00 | C40: 1U125S2SN3FB | D40: OU | E40: HN | F40: RN | H40: ABI0 | N40: AGIR | O40: ASI0 | Q40: No | R40: Mono SM+ | S40: Three Phase - New model 2026 | T40: 5 | U40: LCAC | W40: =IFERROR(VLOOKUP(V:V,$B:$C,2,),"") | Y40: =IFERROR(VLOOKUP(X:X,$B:$C,2,),"") | AA40: =IFERROR(VLOOKUP(Z:Z,$B:$C,2,),"") | AC40: =IFERROR(VLOOKUP(AB:AB,$B:$C,2,),"") | AE40: =IFERROR(VLOOKUP(AD:AD,$B:$C,2,),"") | AG40: =IFERROR(VLOOKUP(AF:AF,$B:$C,2,),"") | AI40: =IFERROR(VLOOKUP(AH:AH,$B:$C,2,),"")
...

Sheet Tabella Traslata
B1: 2 | C1: 3 | D1: 4 | G1: 17 | H1: 18 | I1: 19 | J1: 20 | K1: 21 | N1: 36 | O1: 37 | P1: 38 | Q1: 39 | R1: 40 | S1: 41 | T1: 42 | U1: 43 | V1: 5 | W1: 6 | X1: 7 | Y1: 8 | Z1: 9 | AA1: 10 | AB1: 11 | AC1: 12 | AD1: 13 | AE1: 14 | AF1: 15 | AG1: 16 | AH1: 22 | AI1: 24 | AJ1: 26 | AK1: 28 | AL1: 30 | AM1: 32 | AN1: 34
A2: ID | B2: =VLOOKUP($A:$A,'Matrice Visualizzazione File 1'!$A:$AR,B$1,) -> Material | C2: =VLOOKUP($A:$A,'Matrice Visualizzazione File 1'!$A:$AR,C$1,) -> Model | D2: =VLOOKUP($A:$A,'Matrice Visualizzazione File 1'!$A:$AR,D$1,) -> Unit type | G2: =VLOOKUP($A:$A,'Matrice Visualizzazione File 1'!$A:$AR,G$1,) -> InCatalog | H2: =VLOOKUP($A:$A,'Matrice Visualizzazione File 1'!$A:$AR,H$1,) -> Nota Descritiva | I2: =VLOOKUP($A:$A,'Matrice Visualizzazione File 1'!$A:$AR,I$1,) -> Note Aggiuntive | J2: =VLOOKUP($A:$A,'Matrice Visualizzazione File 1'!$A:$AR,J$1,) -> Min Q.tà | K2: =VLOOKUP($A:$A,'Matrice Visualizzazione File 1'!$A:$AR,K$1,) -> Area | N2: =VLOOKUP($A:$A,'Matrice Visualizzazione File 1'!$A:$AR,N$1,) -> Famiglia | O2: =VLOOKUP($A:$A,'Matrice Visualizzazione File 1'!$A:$AR,O$1,) -> Tipologia | P2: =VLOOKUP($A:$A,'Matrice Visualizzazione File 1'!$A:$AR,P$1,) -> Tecnologia | Q2: =VLOOKUP($A:$A,'Matrice Visualizzazione File 1'!$A:$AR,Q$1,) -> Catalogo | R2: =VLOOKUP($A:$A,'Matrice Visualizzazione File 1'!$A:$AR,R$1,) -> Dimensionali | S2: =VLOOKUP($A:$A,'Matrice Visualizzazione File 1'!$A:$AR,S$1,) -> Scheda Tecnica | T2: =VLOOKUP($A:$A,'Matrice Visualizzazione File 1'!$A:$AR,T$1,) -> Descrizione Capitolato | U2: =VLOOKUP($A:$A,'Matrice Visualizzazione File 1'!$A:$AR,U$1,) -> Descrizione Capitolato Opzionale | ... AN2: =VLOOKUP($A:$A,'Matrice Visualizzazione File 1'!$A:$AR,AN$1,) -> Accessorio 5
A3: Tabella da non Toccare si aggiorna in automatico
V4: Colonne di appoggio per la matrice
A5: ID | B5: Material | C5: Model | D5: Unit type | E5: SalesArea | F5: Sale office | G5: InCatalog | H5: Nota Descritiva | I5: Note Aggiuntive | J5: Min Q.tà | K5: Area | L5: Avviamenti | M5: Accessori | N5: Famiglia | O5: Tipologia | P5: Tecnologia | Q5: Catalogo | R5: Dimensionali | S5: Scheda Tecnica | T5: Descrizione Capitolato | U5: Descrizione Capitolato Opzionale | V5: HN | W5: RN | X5: CN | Y5: Sale office 1 | Z5: Sale Office 2 | AA5: Sale office 3 | AB5: Sale office 4 | AC5: Sale office 5 | AD5: Sale office 6 | AE5: Sale office 7 | AF5: Sale office 8 | AG5: Sale office 9 | AH5: Codice Avviamento 1 | AI5: Codice Avviamento 2 | AJ5: Accessorio 1 | AK5: Accessorio 2 | AL5: Accessorio 3 | AM5: Accessorio 4 | AN5: Accessorio 5
A6: 1 | B6: =IFERROR(VLOOKUP($A:$A,'Matrice Visualizzazione File 1'!$A:$AR,B$1,),"") -> AB97Y0E00 | C6: =IFERROR(VLOOKUP($A:$A,'Matrice Visualizzazione File 1'!$A:$AR,C$1,),"") -> AP71DFMHRA DIZUN | D6: =IFERROR(VLOOKUP($A:$A,'Matrice Visualizzazione File 1'!$A:$AR,D$1,),"") -> IU | E6: =_xlfn.TEXTJOIN("|",TRUE,Tabella_Traslata[[#This Row],[HN]:[CN]]) -> HN|RN | F6: =_xlfn.TEXTJOIN("|",TRUE,Tabella_Traslata[[#This Row],[Sale office 1]:[Sale office 9]]) -> ABI0|AGIR|ASI0 | G6: =IFERROR(VLOOKUP($A:$A,'Matrice Visualizzazione File 1'!$A:$AR,G$1,),"") -> Yes | H6: =IFERROR(VLOOKUP($A:$A,'Matrice Visualizzazione File 1'!$A:$AR,H$1,),"") -> Cabinet | I6: =IFERROR(VLOOKUP($A:$A,'Matrice Visualizzazione File 1'!$A:$AR,I$1,),"") -> 0 | J6: =IFERROR(VLOOKUP($A:$A,'Matrice Visualizzazione File 1'!$A:$AR,J$1,),"") -> 5 | K6: =IFERROR(VLOOKUP($A:$A,'Matrice Visualizzazione File 1'!$A:$AR,K$1,),"") -> Catologue | L6: =_xlfn.TEXTJOIN("|",TRUE,Tabella_Traslata[[#This Row],[Codice Avviamento 1]:[Codice Avviamento 2]]) | M6: =_xlfn.TEXTJOIN("|",TRUE,Tabella_Traslata[[#This Row],[Accessorio 1]:[Accessorio 5]]) | N6: =IFERROR(VLOOKUP($A:$A,'Matrice Visualizzazione File 1'!$A:$AR,N$1,),"") | O6: =IFERROR(VLOOKUP($A:$A,'Matrice Visualizzazione File 1'!$A:$AR,O$1,),"") | P6: =IFERROR(VLOOKUP($A:$A,'Matrice Visualizzazione File 1'!$A:$AR,P$1,),"") | Q6: =IFERROR(VLOOKUP($A:$A,'Matrice Visualizzazione File 1'!$A:$AR,Q$1,),"") | R6: =IFERROR(VLOOKUP($A:$A,'Matrice Visualizzazione File 1'!$A:$AR,R$1,),"") | S6: =IFERROR(VLOOKUP($A:$A,'Matrice Visualizzazione File 1'!$A:$AR,S$1,),"") -> 0 | T6: =IFERROR(VLOOKUP($A:$A,'Matrice Visualizzazione File 1'!$A:$AR,T$1,),"") | U6: =IFERROR(VLOOKUP($A:$A,'Matrice Visualizzazione File 1'!$A:$AR,U$1,),"") | V6: =IF(IFERROR(VLOOKUP($A:$A,'Matrice Visualizzazione File 1'!$A:$AR,V$1,),"")=0,"",IFERROR(VLOOKUP($A:$A,'Matrice Visualizzazione File 1'!$A:$AR,V$1,),"")) -> HN | W6: =IF(IFERROR(VLOOKUP($A:$A,'Matrice Visualizzazione File 1'!$A:$AR,W$1,),"")=0,"",IFERROR(VLOOKUP($A:$A,'Matrice Visualizzazione File 1'!$A:$AR,W$1,),"")) -> RN | X6: =IF(IFERROR(VLOOKUP($A:$A,'Matrice Visualizzazione File 1'!$A:$AR,X$1,),"")=0,"",IFERROR(VLOOKUP($A:$A,'Matrice Visualizzazione File 1'!$A:$AR,X$1,),"")) | Y6: =IF(IFERROR(VLOOKUP($A:$A,'Matrice Visualizzazione File 1'!$A:$AR,Y$1,),"")=0,"",IFERROR(VLOOKUP($A:$A,'Matrice Visualizzazione File 1'!$A:$AR,Y$1,),"")) -> ABI0 | Z6: =IF(IFERROR(VLOOKUP($A:$A,'Matrice Visualizzazione File 1'!$A:$AR,Z$1,),"")=0,"",IFERROR(VLOOKUP($A:$A,'Matrice Visualizzazione File 1'!$A:$AR,Z$1,),"")) | AA6: =IF(IFERROR(VLOOKUP($A:$A,'Matrice Visualizzazione File 1'!$A:$AR,AA$1,),"")=0,"",IFERROR(VLOOKUP($A:$A,'Matrice Visualizzazione File 1'!$A:$AR,AA$1,),"")) | AB6: =IF(IFERROR(VLOOKUP($A:$A,'Matrice Visualizzazione File 1'!$A:$AR,AB$1,),"")=0,"",IFERROR(VLOOKUP($A:$A,'Matrice Visualizzazione File 1'!$A:$AR,AB$1,),"")) | AC6: =IF(IFERROR(VLOOKUP($A:$A,'Matrice Visualizzazione File 1'!$A:$AR,AC$1,),"")=0,"",IFERROR(VLOOKUP($A:$A,'Matrice Visualizzazione File 1'!$A:$AR,AC$1,),"")) | ... AN6: =IF(IFERROR(VLOOKUP($A:$A,'Matrice Visualizzazione File 1'!$A:$AR,AN$1,),"")=0,"",IFERROR(VLOOKUP($A:$A,'Matrice Visualizzazione File 1'!$A:$AR,AN$1,),""))
A7: =A6+1 -> 2 | B7: =IFERROR(VLOOKUP($A:$A,'Matrice Visualizzazione File 1'!$A:$AR,B$1,),"") -> AACKF0E00 | C7: =IFERROR(VLOOKUP($A:$A,'Matrice Visualizzazione File 1'!$A:$AR,C$1,),"") -> 1U71WEMFRA DIZUN | D7: =IFERROR(VLOOKUP($A:$A,'Matrice Visualizzazione File 1'!$A:$AR,D$1,),"") -> OU | E7: =_xlfn.TEXTJOIN("|",TRUE,Tabella_Traslata[[#This Row],[HN]:[CN]]) -> HN|RN | F7: =_xlfn.TEXTJOIN("|",TRUE,Tabella_Traslata[[#This Row],[Sale office 1]:[Sale office 9]]) -> ABI0|AGIR|ASI0 | G7: =IFERROR(VLOOKUP($A:$A,'Matrice Visualizzazione File 1'!$A:$AR,G$1,),"") -> Yes | H7: =IFERROR(VLOOKUP($A:$A,'Matrice Visualizzazione File 1'!$A:$AR,H$1,),"") -> Cabinet | I7: =IFERROR(VLOOKUP($A:$A,'Matrice Visualizzazione File 1'!$A:$AR,I$1,),"") -> 0 | J7: =IFERROR(VLOOKUP($A:$A,'Matrice Visualizzazione File 1'!$A:$AR,J$1,),"") -> 5 | K7: =IFERROR(VLOOKUP($A:$A,'Matrice Visualizzazione File 1'!$A:$AR,K$1,),"") -> Catologue | L7: =_xlfn.TEXTJOIN("|",TRUE,Tabella_Traslata[[#This Row],[Codice Avviamento 1]:[Codice Avviamento 2]]) | M7: =_xlfn.TEXTJOIN("|",TRUE,Tabella_Traslata[[#This Row],[Accessorio 1]:[Accessorio 5]]) | N7: =IFERROR(VLOOKUP($A:$A,'Matrice Visualizzazione File 1'!$A:$AR,N$1,),"") | O7: =IFERROR(VLOOKUP($A:$A,'Matrice Visualizzazione File 1'!$A:$AR,O$1,),"") | P7: =IFERROR(VLOOKUP($A:$A,'Matrice Visualizzazione File 1'!$A:$AR,P$1,),"") | Q7: =IFERROR(VLOOKUP($A:$A,'Matrice Visualizzazione File 1'!$A:$AR,Q$1,),"") | R7: =IFERROR(VLOOKUP($A:$A,'Matrice Visualizzazione File 1'!$A:$AR,R$1,),"") | S7: =IFERROR(VLOOKUP($A:$A,'Matrice Visualizzazione File 1'!$A:$AR,S$1,),"") -> 0 | T7: =IFERROR(VLOOKUP($A:$A,'Matrice Visualizzazione File 1'!$A:$AR,T$1,),"") | U7: =IFERROR(VLOOKUP($A:$A,'Matrice Visualizzazione File 1'!$A:$AR,U$1,),"") | V7: =IF(IFERROR(VLOOKUP($A:$A,'Matrice Visualizzazione File 1'!$A:$AR,V$1,),"")=0,"",IFERROR(VLOOKUP($A:$A,'Matrice Visualizzazione File 1'!$A:$AR,V$1,),"")) -> HN | W7: =IF(IFERROR(VLOOKUP($A:$A,'Matrice Visualizzazione File 1'!$A:$AR,W$1,),"")=0,"",IFERROR(VLOOKUP($A:$A,'Matrice Visualizzazione File 1'!$A:$AR,W$1,),"")) -> RN | X7: =IF(IFERROR(VLOOKUP($A:$A,'Matrice Visualizzazione File 1'!$A:$AR,X$1,),"")=0,"",IFERROR(VLOOKUP($A:$A,'Matrice Visualizzazione File 1'!$A:$AR,X$1,),"")) | Y7: =IF(IFERROR(VLOOKUP($A:$A,'Matrice Visualizzazione File 1'!$A:$AR,Y$1,),"")=0,"",IFERROR(VLOOKUP($A:$A,'Matrice Visualizzazione File 1'!$A:$AR,Y$1,),"")) -> ABI0 | Z7: =IF(IFERROR(VLOOKUP($A:$A,'Matrice Visualizzazione File 1'!$A:$AR,Z$1,),"")=0,"",IFERROR(VLOOKUP($A:$A,'Matrice Visualizzazione File 1'!$A:$AR,Z$1,),"")) | AA7: =IF(IFERROR(VLOOKUP($A:$A,'Matrice Visualizzazione File 1'!$A:$AR,AA$1,),"")=0,"",IFERROR(VLOOKUP($A:$A,'Matrice Visualizzazione File 1'!$A:$AR,AA$1,),"")) | AB7: =IF(IFERROR(VLOOKUP($A:$A,'Matrice Visualizzazione File 1'!$A:$AR,AB$1,),"")=0,"",IFERROR(VLOOKUP($A:$A,'Matrice Visualizzazione File 1'!$A:$AR,AB$1,),"")) | AC7: =IF(IFERROR(VLOOKUP($A:$A,'Matrice Visualizzazione File 1'!$A:$AR,AC$1,),"")=0,"",IFERROR(VLOOKUP($A:$A,'Matrice Visualizzazione File 1'!$A:$AR,AC$1,),"")) | ... AN7: =IF(IFERROR(VLOOKUP($A:$A,'Matrice Visualizzazione File 1'!$A:$AR,AN$1,),"")=0,"",IFERROR(VLOOKUP($A:$A,'Matrice Visualizzazione File 1'!$A:$AR,AN$1,),""))
A8: =A7+1 -> 3 | B8: =IFERROR(VLOOKUP($A:$A,'Matrice Visualizzazione File 1'!$A:$AR,B$1,),"") -> 0 | C8: =IFERROR(VLOOKUP($A:$A,'Matrice Visualizzazione File 1'!$A:$AR,C$1,),"") -> 0 | D8: =IFERROR(VLOOKUP($A:$A,'Matrice Visualizzazione File 1'!$A:$AR,D$1,),"") -> 0 | E8: =_xlfn.TEXTJOIN("|",TRUE,Tabella_Traslata[[#This Row],[HN]:[CN]]) -> ---|--- | F8: =_xlfn.TEXTJOIN("|",TRUE,Tabella_Traslata[[#This Row],[Sale office 1]:[Sale office 9]]) | G8: =IFERROR(VLOOKUP($A:$A,'Matrice Visualizzazione File 1'!$A:$AR,G$1,),"") -> 0 | H8: =IFERROR(VLOOKUP($A:$A,'Matrice Visualizzazione File 1'!$A:$AR,H$1,),"") -> 0 | I8: =IFERROR(VLOOKUP($A:$A,'Matrice Visualizzazione File 1'!$A:$AR,I$1,),"") -> 0 | J8: =IFERROR(VLOOKUP($A:$A,'Matrice Visualizzazione File 1'!$A:$AR,J$1,),"") -> 0 | K8: =IFERROR(VLOOKUP($A:$A,'Matrice Visualizzazione File 1'!$A:$AR,K$1,),"") -> 0 | L8: =_xlfn.TEXTJOIN("|",TRUE,Tabella_Traslata[[#This Row],[Codice Avviamento 1]:[Codice Avviamento 2]]) | M8: =_xlfn.TEXTJOIN("|",TRUE,Tabella_Traslata[[#This Row],[Accessorio 1]:[Accessorio 5]]) | N8: =IFERROR(VLOOKUP($A:$A,'Matrice Visualizzazione File 1'!$A:$AR,N$1,),"") | O8: =IFERROR(VLOOKUP($A:$A,'Matrice Visualizzazione File 1'!$A:$AR,O$1,),"") | P8: =IFERROR(VLOOKUP($A:$A,'Matrice Visualizzazione File 1'!$A:$AR,P$1,),"") | Q8: =IFERROR(VLOOKUP($A:$A,'Matrice Visualizzazione File 1'!$A:$AR,Q$1,),"") | R8: =IFERROR(VLOOKUP($A:$A,'Matrice Visualizzazione File 1'!$A:$AR,R$1,),"") | S8: =IFERROR(VLOOKUP($A:$A,'Matrice Visualizzazione File 1'!$A:$AR,S$1,),"") -> 0 | T8: =IFERROR(VLOOKUP($A:$A,'Matrice Visualizzazione File 1'!$A:$AR,T$1,),"") | U8: =IFERROR(VLOOKUP($A:$A,'Matrice Visualizzazione File 1'!$A:$AR,U$1,),"") | V8: =IF(IFERROR(VLOOKUP($A:$A,'Matrice Visualizzazione File 1'!$A:$AR,V$1,),"")=0,"",IFERROR(VLOOKUP($A:$A,'Matrice Visualizzazione File 1'!$A:$AR,V$1,),"")) -> --- | W8: =IF(IFERROR(VLOOKUP($A:$A,'Matrice Visualizzazione File 1'!$A:$AR,W$1,),"")=0,"",IFERROR(VLOOKUP($A:$A,'Matrice Visualizzazione File 1'!$A:$AR,W$1,),"")) -> --- | X8: =IF(IFERROR(VLOOKUP($A:$A,'Matrice Visualizzazione File 1'!$A:$AR,X$1,),"")=0,"",IFERROR(VLOOKUP($A:$A,'Matrice Visualizzazione File 1'!$A:$AR,X$1,),"")) | Y8: =IF(IFERROR(VLOOKUP($A:$A,'Matrice Visualizzazione File 1'!$A:$AR,Y$1,),"")=0,"",IFERROR(VLOOKUP($A:$A,'Matrice Visualizzazione File 1'!$A:$AR,Y$1,),"")) | Z8: =IF(IFERROR(VLOOKUP($A:$A,'Matrice Visualizzazione File 1'!$A:$AR,Z$1,),"")=0,"",IFERROR(VLOOKUP($A:$A,'Matrice Visualizzazione File 1'!$A:$AR,Z$1,),"")) | AA8: =IF(IFERROR(VLOOKUP($A:$A,'Matrice Visualizzazione File 1'!$A:$AR,AA$1,),"")=0,"",IFERROR(VLOOKUP($A:$A,'Matrice Visualizzazione File 1'!$A:$AR,AA$1,),"")) | AB8: =IF(IFERROR(VLOOKUP($A:$A,'Matrice Visualizzazione File 1'!$A:$AR,AB$1,),"")=0,"",IFERROR(VLOOKUP($A:$A,'Matrice Visualizzazione File 1'!$A:$AR,AB$1,),"")) | AC8: =IF(IFERROR(VLOOKUP($A:$A,'Matrice Visualizzazione File 1'!$A:$AR,AC$1,),"")=0,"",IFERROR(VLOOKUP($A:$A,'Matrice Visualizzazione File 1'!$A:$AR,AC$1,),"")) | ... AN8: =IF(IFERROR(VLOOKUP($A:$A,'Matrice Visualizzazione File 1'!$A:$AR,AN$1,),"")=0,"",IFERROR(VLOOKUP($A:$A,'Matrice Visualizzazione File 1'!$A:$AR,AN$1,),""))
A9: =A8+1 -> 4 | B9: =IFERROR(VLOOKUP($A:$A,'Matrice Visualizzazione File 1'!$A:$AR,B$1,),"") -> AAC160E00 | C9: =IFERROR(VLOOKUP($A:$A,'Matrice Visualizzazione File 1'!$A:$AR,C$1,),"") | D9: =IFERROR(VLOOKUP($A:$A,'Matrice Visualizzazione File 1'!$A:$AR,D$1,),"") -> IU | E9: =_xlfn.TEXTJOIN("|",TRUE,Tabella_Traslata[[#This Row],[HN]:[CN]]) -> HN|RN | F9: =_xlfn.TEXTJOIN("|",TRUE,Tabella_Traslata[[#This Row],[Sale office 1]:[Sale office 9]]) -> ABI0|AGIR|ASI0 | G9: =IFERROR(VLOOKUP($A:$A,'Matrice Visualizzazione File 1'!$A:$AR,G$1,),"") -> Yes | H9: =IFERROR(VLOOKUP($A:$A,'Matrice Visualizzazione File 1'!$A:$AR,H$1,),"") -> Expert Nordic | I9: =IFERROR(VLOOKUP($A:$A,'Matrice Visualizzazione File 1'!$A:$AR,I$1,),"") -> 0 | J9: =IFERROR(VLOOKUP($A:$A,'Matrice Visualizzazione File 1'!$A:$AR,J$1,),"") -> 5 | K9: =IFERROR(VLOOKUP($A:$A,'Matrice Visualizzazione File 1'!$A:$AR,K$1,),"") -> Catologue | L9: =_xlfn.TEXTJOIN("|",TRUE,Tabella_Traslata[[#This Row],[Codice Avviamento 1]:[Codice Avviamento 2]]) | M9: =_xlfn.TEXTJOIN("|",TRUE,Tabella_Traslata[[#This Row],[Accessorio 1]:[Accessorio 5]]) | N9: =IFERROR(VLOOKUP($A:$A,'Matrice Visualizzazione File 1'!$A:$AR,N$1,),"") | O9: =IFERROR(VLOOKUP($A:$A,'Matrice Visualizzazione File 1'!$A:$AR,O$1,),"") | P9: =IFERROR(VLOOKUP($A:$A,'Matrice Visualizzazione File 1'!$A:$AR,P$1,),"") | Q9: =IFERROR(VLOOKUP($A:$A,'Matrice Visualizzazione File 1'!$A:$AR,Q$1,),"") | R9: =IFERROR(VLOOKUP($A:$A,'Matrice Visualizzazione File 1'!$A:$AR,R$1,),"") | S9: =IFERROR(VLOOKUP($A:$A,'Matrice Visualizzazione File 1'!$A:$AR,S$1,),"") -> 0 | T9: =IFERROR(VLOOKUP($A:$A,'Matrice Visualizzazione File 1'!$A:$AR,T$1,),"") | U9: =IFERROR(VLOOKUP($A:$A,'Matrice Visualizzazione File 1'!$A:$AR,U$1,),"") | V9: =IF(IFERROR(VLOOKUP($A:$A,'Matrice Visualizzazione File 1'!$A:$AR,V$1,),"")=0,"",IFERROR(VLOOKUP($A:$A,'Matrice Visualizzazione File 1'!$A:$AR,V$1,),"")) -> HN | W9: =IF(IFERROR(VLOOKUP($A:$A,'Matrice Visualizzazione File 1'!$A:$AR,W$1,),"")=0,"",IFERROR(VLOOKUP($A:$A,'Matrice Visualizzazione File 1'!$A:$AR,W$1,),"")) -> RN | X9: =IF(IFERROR(VLOOKUP($A:$A,'Matrice Visualizzazione File 1'!$A:$AR,X$1,),"")=0,"",IFERROR(VLOOKUP($A:$A,'Matrice Visualizzazione File 1'!$A:$AR,X$1,),"")) | Y9: =IF(IFERROR(VLOOKUP($A:$A,'Matrice Visualizzazione File 1'!$A:$AR,Y$1,),"")=0,"",IFERROR(VLOOKUP($A:$A,'Matrice Visualizzazione File 1'!$A:$AR,Y$1,),"")) -> ABI0 | Z9: =IF(IFERROR(VLOOKUP($A:$A,'Matrice Visualizzazione File 1'!$A:$AR,Z$1,),"")=0,"",IFERROR(VLOOKUP($A:$A,'Matrice Visualizzazione File 1'!$A:$AR,Z$1,),"")) | AA9: =IF(IFERROR(VLOOKUP($A:$A,'Matrice Visualizzazione File 1'!$A:$AR,AA$1,),"")=0,"",IFERROR(VLOOKUP($A:$A,'Matrice Visualizzazione File 1'!$A:$AR,AA$1,),"")) | AB9: =IF(IFERROR(VLOOKUP($A:$A,'Matrice Visualizzazione File 1'!$A:$AR,AB$1,),"")=0,"",IFERROR(VLOOKUP($A:$A,'Matrice Visualizzazione File 1'!$A:$AR,AB$1,),"")) | AC9: =IF(IFERROR(VLOOKUP($A:$A,'Matrice Visualizzazione File 1'!$A:$AR,AC$1,),"")=0,"",IFERROR(VLOOKUP($A:$A,'Matrice Visualizzazione File 1'!$A:$AR,AC$1,),"")) | ... AN9: =IF(IFERROR(VLOOKUP($A:$A,'Matrice Visualizzazione File 1'!$A:$AR,AN$1,),"")=0,"",IFERROR(VLOOKUP($A:$A,'Matrice Visualizzazione File 1'!$A:$AR,AN$1,),""))
A10: =A9+1 -> 5 | B10: =IFERROR(VLOOKUP($A:$A,'Matrice Visualizzazione File 1'!$A:$AR,B$1,),"") -> AAC180E00 | C10: =IFERROR(VLOOKUP($A:$A,'Matrice Visualizzazione File 1'!$A:$AR,C$1,),"") -> 1U25KEHFRA-NR | D10: =IFERROR(VLOOKUP($A:$A,'Matrice Visualizzazione File 1'!$A:$AR,D$1,),"") -> OU | E10: =_xlfn.TEXTJOIN("|",TRUE,Tabella_Traslata[[#This Row],[HN]:[CN]]) -> HN|RN | F10: =_xlfn.TEXTJOIN("|",TRUE,Tabella_Traslata[[#This Row],[Sale office 1]:[Sale office 9]]) -> ABI0|AGIR|ASI0 | G10: =IFERROR(VLOOKUP($A:$A,'Matrice Visualizzazione File 1'!$A:$AR,G$1,),"") -> Yes | H10: =IFERROR(VLOOKUP($A:$A,'Matrice Visualizzazione File 1'!$A:$AR,H$1,),"") -> Expert Nordic | I10: =IFERROR(VLOOKUP($A:$A,'Matrice Visualizzazione File 1'!$A:$AR,I$1,),"") -> 0 | J10: =IFERROR(VLOOKUP($A:$A,'Matrice Visualizzazione File 1'!$A:$AR,J$1,),"") -> 5 | K10: =IFERROR(VLOOKUP($A:$A,'Matrice Visualizzazione File 1'!$A:$AR,K$1,),"") -> Catologue | L10: =_xlfn.TEXTJOIN("|",TRUE,Tabella_Traslata[[#This Row],[Codice Avviamento 1]:[Codice Avviamento 2]]) | M10: =_xlfn.TEXTJOIN("|",TRUE,Tabella_Traslata[[#This Row],[Accessorio 1]:[Accessorio 5]]) | N10: =IFERROR(VLOOKUP($A:$A,'Matrice Visualizzazione File 1'!$A:$AR,N$1,),"") | O10: =IFERROR(VLOOKUP($A:$A,'Matrice Visualizzazione File 1'!$A:$AR,O$1,),"") | P10: =IFERROR(VLOOKUP($A:$A,'Matrice Visualizzazione File 1'!$A:$AR,P$1,),"") | Q10: =IFERROR(VLOOKUP($A:$A,'Matrice Visualizzazione File 1'!$A:$AR,Q$1,),"") | R10: =IFERROR(VLOOKUP($A:$A,'Matrice Visualizzazione File 1'!$A:$AR,R$1,),"") | S10: =IFERROR(VLOOKUP($A:$A,'Matrice Visualizzazione File 1'!$A:$AR,S$1,),"") -> 0 | T10: =IFERROR(VLOOKUP($A:$A,'Matrice Visualizzazione File 1'!$A:$AR,T$1,),"") | U10: =IFERROR(VLOOKUP($A:$A,'Matrice Visualizzazione File 1'!$A:$AR,U$1,),"") | V10: =IF(IFERROR(VLOOKUP($A:$A,'Matrice Visualizzazione File 1'!$A:$AR,V$1,),"")=0,"",IFERROR(VLOOKUP($A:$A,'Matrice Visualizzazione File 1'!$A:$AR,V$1,),"")) -> HN | W10: =IF(IFERROR(VLOOKUP($A:$A,'Matrice Visualizzazione File 1'!$A:$AR,W$1,),"")=0,"",IFERROR(VLOOKUP($A:$A,'Matrice Visualizzazione File 1'!$A:$AR,W$1,),"")) -> RN | X10: =IF(IFERROR(VLOOKUP($A:$A,'Matrice Visualizzazione File 1'!$A:$AR,X$1,),"")=0,"",IFERROR(VLOOKUP($A:$A,'Matrice Visualizzazione File 1'!$A:$AR,X$1,),"")) | Y10: =IF(IFERROR(VLOOKUP($A:$A,'Matrice Visualizzazione File 1'!$A:$AR,Y$1,),"")=0,"",IFERROR(VLOOKUP($A:$A,'Matrice Visualizzazione File 1'!$A:$AR,Y$1,),"")) -> ABI0 | Z10: =IF(IFERROR(VLOOKUP($A:$A,'Matrice Visualizzazione File 1'!$A:$AR,Z$1,),"")=0,"",IFERROR(VLOOKUP($A:$A,'Matrice Visualizzazione File 1'!$A:$AR,Z$1,),"")) | AA10: =IF(IFERROR(VLOOKUP($A:$A,'Matrice Visualizzazione File 1'!$A:$AR,AA$1,),"")=0,"",IFERROR(VLOOKUP($A:$A,'Matrice Visualizzazione File 1'!$A:$AR,AA$1,),"")) | AB10: =IF(IFERROR(VLOOKUP($A:$A,'Matrice Visualizzazione File 1'!$A:$AR,AB$1,),"")=0,"",IFERROR(VLOOKUP($A:$A,'Matrice Visualizzazione File 1'!$A:$AR,AB$1,),"")) | AC10: =IF(IFERROR(VLOOKUP($A:$A,'Matrice Visualizzazione File 1'!$A:$AR,AC$1,),"")=0,"",IFERROR(VLOOKUP($A:$A,'Matrice Visualizzazione File 1'!$A:$AR,AC$1,),"")) | ... AN10: =IF(IFERROR(VLOOKUP($A:$A,'Matrice Visualizzazione File 1'!$A:$AR,AN$1,),"")=0,"",IFERROR(VLOOKUP($A:$A,'Matrice Visualizzazione File 1'!$A:$AR,AN$1,),""))
A11: =A10+1 -> 6 | B11: =IFERROR(VLOOKUP($A:$A,'Matrice Visualizzazione File 1'!$A:$AR,B$1,),"") -> AAC170E00 | C11: =IFERROR(VLOOKUP($A:$A,'Matrice Visualizzazione File 1'!$A:$AR,C$1,),"") -> AS35XCHHRA-NR | D11: =IFERROR(VLOOKUP($A:$A,'Matrice Visualizzazione File 1'!$A:$AR,D$1,),"") -> IU | E11: =_xlfn.TEXTJOIN("|",TRUE,Tabella_Traslata[[#This Row],[HN]:[CN]]) -> HN|RN | F11: =_xlfn.TEXTJOIN("|",TRUE,Tabella_Traslata[[#This Row],[Sale office 1]:[Sale office 9]]) -> ABI0|AGIR|ASI0 | G11: =IFERROR(VLOOKUP($A:$A,'Matrice Visualizzazione File 1'!$A:$AR,G$1,),"") -> Yes | H11: =IFERROR(VLOOKUP($A:$A,'Matrice Visualizzazione File 1'!$A:$AR,H$1,),"") -> Expert Nordic | I11: =IFERROR(VLOOKUP($A:$A,'Matrice Visualizzazione File 1'!$A:$AR,I$1,),"") -> 0 | J11: =IFERROR(VLOOKUP($A:$A,'Matrice Visualizzazione File 1'!$A:$AR,J$1,),"") -> 5 | K11: =IFERROR(VLOOKUP($A:$A,'Matrice Visualizzazione File 1'!$A:$AR,K$1,),"") -> Catologue | L11: =_xlfn.TEXTJOIN("|",TRUE,Tabella_Traslata[[#This Row],[Codice Avviamento 1]:[Codice Avviamento 2]]) | M11: =_xlfn.TEXTJOIN("|",TRUE,Tabella_Traslata[[#This Row],[Accessorio 1]:[Accessorio 5]]) | N11: =IFERROR(VLOOKUP($A:$A,'Matrice Visualizzazione File 1'!$A:$AR,N$1,),"") | O11: =IFERROR(VLOOKUP($A:$A,'Matrice Visualizzazione File 1'!$A:$AR,O$1,),"") | P11: =IFERROR(VLOOKUP($A:$A,'Matrice Visualizzazione File 1'!$A:$AR,P$1,),"") | Q11: =IFERROR(VLOOKUP($A:$A,'Matrice Visualizzazione File 1'!$A:$AR,Q$1,),"") | R11: =IFERROR(VLOOKUP($A:$A,'Matrice Visualizzazione File 1'!$A:$AR,R$1,),"") | S11: =IFERROR(VLOOKUP($A:$A,'Matrice Visualizzazione File 1'!$A:$AR,S$1,),"") -> 0 | T11: =IFERROR(VLOOKUP($A:$A,'Matrice Visualizzazione File 1'!$A:$AR,T$1,),"") | U11: =IFERROR(VLOOKUP($A:$A,'Matrice Visualizzazione File 1'!$A:$AR,U$1,),"") | V11: =IF(IFERROR(VLOOKUP($A:$A,'Matrice Visualizzazione File 1'!$A:$AR,V$1,),"")=0,"",IFERROR(VLOOKUP($A:$A,'Matrice Visualizzazione File 1'!$A:$AR,V$1,),"")) -> HN | W11: =IF(IFERROR(VLOOKUP($A:$A,'Matrice Visualizzazione File 1'!$A:$AR,W$1,),"")=0,"",IFERROR(VLOOKUP($A:$A,'Matrice Visualizzazione File 1'!$A:$AR,W$1,),"")) -> RN | X11: =IF(IFERROR(VLOOKUP($A:$A,'Matrice Visualizzazione File 1'!$A:$AR,X$1,),"")=0,"",IFERROR(VLOOKUP($A:$A,'Matrice Visualizzazione File 1'!$A:$AR,X$1,),"")) | Y11: =IF(IFERROR(VLOOKUP($A:$A,'Matrice Visualizzazione File 1'!$A:$AR,Y$1,),"")=0,"",IFERROR(VLOOKUP($A:$A,'Matrice Visualizzazione File 1'!$A:$AR,Y$1,),"")) -> ABI0 | Z11: =IF(IFERROR(VLOOKUP($A:$A,'Matrice Visualizzazione File 1'!$A:$AR,Z$1,),"")=0,"",IFERROR(VLOOKUP($A:$A,'Matrice Visualizzazione File 1'!$A:$AR,Z$1,),"")) | AA11: =IF(IFERROR(VLOOKUP($A:$A,'Matrice Visualizzazione File 1'!$A:$AR,AA$1,),"")=0,"",IFERROR(VLOOKUP($A:$A,'Matrice Visualizzazione File 1'!$A:$AR,AA$1,),"")) | AB11: =IF(IFERROR(VLOOKUP($A:$A,'Matrice Visualizzazione File 1'!$A:$AR,AB$1,),"")=0,"",IFERROR(VLOOKUP($A:$A,'Matrice Visualizzazione File 1'!$A:$AR,AB$1,),"")) | AC11: =IF(IFERROR(VLOOKUP($A:$A,'Matrice Visualizzazione File 1'!$A:$AR,AC$1,),"")=0,"",IFERROR(VLOOKUP($A:$A,'Matrice Visualizzazione File 1'!$A:$AR,AC$1,),"")) | ... AN11: =IF(IFERROR(VLOOKUP($A:$A,'Matrice Visualizzazione File 1'!$A:$AR,AN$1,),"")=0,"",IFERROR(VLOOKUP($A:$A,'Matrice Visualizzazione File 1'!$A:$AR,AN$1,),""))
A12: =A11+1 -> 7 | B12: =IFERROR(VLOOKUP($A:$A,'Matrice Visualizzazione File 1'!$A:$AR,B$1,),"") -> AAC190E00 | C12: =IFERROR(VLOOKUP($A:$A,'Matrice Visualizzazione File 1'!$A:$AR,C$1,),"") -> 1U35KEHFRA-NR | D12: =IFERROR(VLOOKUP($A:$A,'Matrice Visualizzazione File 1'!$A:$AR,D$1,),"") -> OU | E12: =_xlfn.TEXTJOIN("|",TRUE,Tabella_Traslata[[#This Row],[HN]:[CN]]) -> HN|RN | F12: =_xlfn.TEXTJOIN("|",TRUE,Tabella_Traslata[[#This Row],[Sale office 1]:[Sale office 9]]) -> ABI0|AGIR|ASI0 | G12: =IFERROR(VLOOKUP($A:$A,'Matrice Visualizzazione File 1'!$A:$AR,G$1,),"") -> Yes | H12: =IFERROR(VLOOKUP($A:$A,'Matrice Visualizzazione File 1'!$A:$AR,H$1,),"") -> Expert Nordic | I12: =IFERROR(VLOOKUP($A:$A,'Matrice Visualizzazione File 1'!$A:$AR,I$1,),"") -> 0 | J12: =IFERROR(VLOOKUP($A:$A,'Matrice Visualizzazione File 1'!$A:$AR,J$1,),"") -> 5 | K12: =IFERROR(VLOOKUP($A:$A,'Matrice Visualizzazione File 1'!$A:$AR,K$1,),"") -> Catologue | L12: =_xlfn.TEXTJOIN("|",TRUE,Tabella_Traslata[[#This Row],[Codice Avviamento 1]:[Codice Avviamento 2]]) | M12: =_xlfn.TEXTJOIN("|",TRUE,Tabella_Traslata[[#This Row],[Accessorio 1]:[Accessorio 5]]) | N12: =IFERROR(VLOOKUP($A:$A,'Matrice Visualizzazione File 1'!$A:$AR,N$1,),"") | O12: =IFERROR(VLOOKUP($A:$A,'Matrice Visualizzazione File 1'!$A:$AR,O$1,),"") | P12: =IFERROR(VLOOKUP($A:$A,'Matrice Visualizzazione File 1'!$A:$AR,P$1,),"") | Q12: =IFERROR(VLOOKUP($A:$A,'Matrice Visualizzazione File 1'!$A:$AR,Q$1,),"") | R12: =IFERROR(VLOOKUP($A:$A,'Matrice Visualizzazione File 1'!$A:$AR,R$1,),"") | S12: =IFERROR(VLOOKUP($A:$A,'Matrice Visualizzazione File 1'!$A:$AR,S$1,),"") -> 0 | T12: =IFERROR(VLOOKUP($A:$A,'Matrice Visualizzazione File 1'!$A:$AR,T$1,),"") | U12: =IFERROR(VLOOKUP($A:$A,'Matrice Visualizzazione File 1'!$A:$AR,U$1,),"") | V12: =IF(IFERROR(VLOOKUP($A:$A,'Matrice Visualizzazione File 1'!$A:$AR,V$1,),"")=0,"",IFERROR(VLOOKUP($A:$A,'Matrice Visualizzazione File 1'!$A:$AR,V$1,),"")) -> HN | W12: =IF(IFERROR(VLOOKUP($A:$A,'Matrice Visualizzazione File 1'!$A:$AR,W$1,),"")=0,"",IFERROR(VLOOKUP($A:$A,'Matrice Visualizzazione File 1'!$A:$AR,W$1,),"")) -> RN | X12: =IF(IFERROR(VLOOKUP($A:$A,'Matrice Visualizzazione File 1'!$A:$AR,X$1,),"")=0,"",IFERROR(VLOOKUP($A:$A,'Matrice Visualizzazione File 1'!$A:$AR,X$1,),"")) | Y12: =IF(IFERROR(VLOOKUP($A:$A,'Matrice Visualizzazione File 1'!$A:$AR,Y$1,),"")=0,"",IFERROR(VLOOKUP($A:$A,'Matrice Visualizzazione File 1'!$A:$AR,Y$1,),"")) -> ABI0 | Z12: =IF(IFERROR(VLOOKUP($A:$A,'Matrice Visualizzazione File 1'!$A:$AR,Z$1,),"")=0,"",IFERROR(VLOOKUP($A:$A,'Matrice Visualizzazione File 1'!$A:$AR,Z$1,),"")) | AA12: =IF(IFERROR(VLOOKUP($A:$A,'Matrice Visualizzazione File 1'!$A:$AR,AA$1,),"")=0,"",IFERROR(VLOOKUP($A:$A,'Matrice Visualizzazione File 1'!$A:$AR,AA$1,),"")) | AB12: =IF(IFERROR(VLOOKUP($A:$A,'Matrice Visualizzazione File 1'!$A:$AR,AB$1,),"")=0,"",IFERROR(VLOOKUP($A:$A,'Matrice Visualizzazione File 1'!$A:$AR,AB$1,),"")) | AC12: =IF(IFERROR(VLOOKUP($A:$A,'Matrice Visualizzazione File 1'!$A:$AR,AC$1,),"")=0,"",IFERROR(VLOOKUP($A:$A,'Matrice Visualizzazione File 1'!$A:$AR,AC$1,),"")) | ... AN12: =IF(IFERROR(VLOOKUP($A:$A,'Matrice Visualizzazione File 1'!$A:$AR,AN$1,),"")=0,"",IFERROR(VLOOKUP($A:$A,'Matrice Visualizzazione File 1'!$A:$AR,AN$1,),""))
A13: =A12+1 -> 8 | B13: =IFERROR(VLOOKUP($A:$A,'Matrice Visualizzazione File 1'!$A:$AR,B$1,),"") -> AABQN6E00 | C13: =IFERROR(VLOOKUP($A:$A,'Matrice Visualizzazione File 1'!$A:$AR,C$1,),"") -> 1U35MEHFRA-1 | D13: =IFERROR(VLOOKUP($A:$A,'Matrice Visualizzazione File 1'!$A:$AR,D$1,),"") -> OU | E13: =_xlfn.TEXTJOIN("|",TRUE,Tabella_Traslata[[#This Row],[HN]:[CN]]) -> RN | F13: =_xlfn.TEXTJOIN("|",TRUE,Tabella_Traslata[[#This Row],[Sale office 1]:[Sale office 9]]) -> AGIR|ASI0 | G13: =IFERROR(VLOOKUP($A:$A,'Matrice Visualizzazione File 1'!$A:$AR,G$1,),"") -> Yes | H13: =IFERROR(VLOOKUP($A:$A,'Matrice Visualizzazione File 1'!$A:$AR,H$1,),"") -> Flexis Nordic | I13: =IFERROR(VLOOKUP($A:$A,'Matrice Visualizzazione File 1'!$A:$AR,I$1,),"") -> 0 | J13: =IFERROR(VLOOKUP($A:$A,'Matrice Visualizzazione File 1'!$A:$AR,J$1,),"") -> 5 | K13: =IFERROR(VLOOKUP($A:$A,'Matrice Visualizzazione File 1'!$A:$AR,K$1,),"") -> Catologue | L13: =_xlfn.TEXTJOIN("|",TRUE,Tabella_Traslata[[#This Row],[Codice Avviamento 1]:[Codice Avviamento 2]]) | M13: =_xlfn.TEXTJOIN("|",TRUE,Tabella_Traslata[[#This Row],[Accessorio 1]:[Accessorio 5]]) | N13: =IFERROR(VLOOKUP($A:$A,'Matrice Visualizzazione File 1'!$A:$AR,N$1,),"") | O13: =IFERROR(VLOOKUP($A:$A,'Matrice Visualizzazione File 1'!$A:$AR,O$1,),"") | P13: =IFERROR(VLOOKUP($A:$A,'Matrice Visualizzazione File 1'!$A:$AR,P$1,),"") | Q13: =IFERROR(VLOOKUP($A:$A,'Matrice Visualizzazione File 1'!$A:$AR,Q$1,),"") | R13: =IFERROR(VLOOKUP($A:$A,'Matrice Visualizzazione File 1'!$A:$AR,R$1,),"") | S13: =IFERROR(VLOOKUP($A:$A,'Matrice Visualizzazione File 1'!$A:$AR,S$1,),"") -> 0 | T13: =IFERROR(VLOOKUP($A:$A,'Matrice Visualizzazione File 1'!$A:$AR,T$1,),"") | U13: =IFERROR(VLOOKUP($A:$A,'Matrice Visualizzazione File 1'!$A:$AR,U$1,),"") | V13: =IF(IFERROR(VLOOKUP($A:$A,'Matrice Visualizzazione File 1'!$A:$AR,V$1,),"")=0,"",IFERROR(VLOOKUP($A:$A,'Matrice Visualizzazione File 1'!$A:$AR,V$1,),"")) | W13: =IF(IFERROR(VLOOKUP($A:$A,'Matrice Visualizzazione File 1'!$A:$AR,W$1,),"")=0,"",IFERROR(VLOOKUP($A:$A,'Matrice Visualizzazione File 1'!$A:$AR,W$1,),"")) -> RN | X13: =IF(IFERROR(VLOOKUP($A:$A,'Matrice Visualizzazione File 1'!$A:$AR,X$1,),"")=0,"",IFERROR(VLOOKUP($A:$A,'Matrice Visualizzazione File 1'!$A:$AR,X$1,),"")) | Y13: =IF(IFERROR(VLOOKUP($A:$A,'Matrice Visualizzazione File 1'!$A:$AR,Y$1,),"")=0,"",IFERROR(VLOOKUP($A:$A,'Matrice Visualizzazione File 1'!$A:$AR,Y$1,),"")) | Z13: =IF(IFERROR(VLOOKUP($A:$A,'Matrice Visualizzazione File 1'!$A:$AR,Z$1,),"")=0,"",IFERROR(VLOOKUP($A:$A,'Matrice Visualizzazione File 1'!$A:$AR,Z$1,),"")) | AA13: =IF(IFERROR(VLOOKUP($A:$A,'Matrice Visualizzazione File 1'!$A:$AR,AA$1,),"")=0,"",IFERROR(VLOOKUP($A:$A,'Matrice Visualizzazione File 1'!$A:$AR,AA$1,),"")) | AB13: =IF(IFERROR(VLOOKUP($A:$A,'Matrice Visualizzazione File 1'!$A:$AR,AB$1,),"")=0,"",IFERROR(VLOOKUP($A:$A,'Matrice Visualizzazione File 1'!$A:$AR,AB$1,),"")) | AC13: =IF(IFERROR(VLOOKUP($A:$A,'Matrice Visualizzazione File 1'!$A:$AR,AC$1,),"")=0,"",IFERROR(VLOOKUP($A:$A,'Matrice Visualizzazione File 1'!$A:$AR,AC$1,),"")) | ... AN13: =IF(IFERROR(VLOOKUP($A:$A,'Matrice Visualizzazione File 1'!$A:$AR,AN$1,),"")=0,"",IFERROR(VLOOKUP($A:$A,'Matrice Visualizzazione File 1'!$A:$AR,AN$1,),""))
A14: =A13+1 -> 9 | B14: =IFERROR(VLOOKUP($A:$A,'Matrice Visualizzazione File 1'!$A:$AR,B$1,),"") -> AAC152E00 | C14: =IFERROR(VLOOKUP($A:$A,'Matrice Visualizzazione File 1'!$A:$AR,C$1,),"") -> 1U50KEFFRA-1 | D14: =IFERROR(VLOOKUP($A:$A,'Matrice Visualizzazione File 1'!$A:$AR,D$1,),"") -> OU | E14: =_xlfn.TEXTJOIN("|",TRUE,Tabella_Traslata[[#This Row],[HN]:[CN]]) -> RN | F14: =_xlfn.TEXTJOIN("|",TRUE,Tabella_Traslata[[#This Row],[Sale office 1]:[Sale office 9]]) -> AGIR|ASI0 | G14: =IFERROR(VLOOKUP($A:$A,'Matrice Visualizzazione File 1'!$A:$AR,G$1,),"") -> Yes | H14: =IFERROR(VLOOKUP($A:$A,'Matrice Visualizzazione File 1'!$A:$AR,H$1,),"") -> Flexis Nordic | I14: =IFERROR(VLOOKUP($A:$A,'Matrice Visualizzazione File 1'!$A:$AR,I$1,),"") -> 0 | J14: =IFERROR(VLOOKUP($A:$A,'Matrice Visualizzazione File 1'!$A:$AR,J$1,),"") -> 5 | K14: =IFERROR(VLOOKUP($A:$A,'Matrice Visualizzazione File 1'!$A:$AR,K$1,),"") -> Catologue | L14: =_xlfn.TEXTJOIN("|",TRUE,Tabella_Traslata[[#This Row],[Codice Avviamento 1]:[Codice Avviamento 2]]) | M14: =_xlfn.TEXTJOIN("|",TRUE,Tabella_Traslata[[#This Row],[Accessorio 1]:[Accessorio 5]]) | N14: =IFERROR(VLOOKUP($A:$A,'Matrice Visualizzazione File 1'!$A:$AR,N$1,),"") | O14: =IFERROR(VLOOKUP($A:$A,'Matrice Visualizzazione File 1'!$A:$AR,O$1,),"") | P14: =IFERROR(VLOOKUP($A:$A,'Matrice Visualizzazione File 1'!$A:$AR,P$1,),"") | Q14: =IFERROR(VLOOKUP($A:$A,'Matrice Visualizzazione File 1'!$A:$AR,Q$1,),"") | R14: =IFERROR(VLOOKUP($A:$A,'Matrice Visualizzazione File 1'!$A:$AR,R$1,),"") | S14: =IFERROR(VLOOKUP($A:$A,'Matrice Visualizzazione File 1'!$A:$AR,S$1,),"") -> 0 | T14: =IFERROR(VLOOKUP($A:$A,'Matrice Visualizzazione File 1'!$A:$AR,T$1,),"") | U14: =IFERROR(VLOOKUP($A:$A,'Matrice Visualizzazione File 1'!$A:$AR,U$1,),"") | V14: =IF(IFERROR(VLOOKUP($A:$A,'Matrice Visualizzazione File 1'!$A:$AR,V$1,),"")=0,"",IFERROR(VLOOKUP($A:$A,'Matrice Visualizzazione File 1'!$A:$AR,V$1,),"")) | W14: =IF(IFERROR(VLOOKUP($A:$A,'Matrice Visualizzazione File 1'!$A:$AR,W$1,),"")=0,"",IFERROR(VLOOKUP($A:$A,'Matrice Visualizzazione File 1'!$A:$AR,W$1,),"")) -> RN | X14: =IF(IFERROR(VLOOKUP($A:$A,'Matrice Visualizzazione File 1'!$A:$AR,X$1,),"")=0,"",IFERROR(VLOOKUP($A:$A,'Matrice Visualizzazione File 1'!$A:$AR,X$1,),"")) | Y14: =IF(IFERROR(VLOOKUP($A:$A,'Matrice Visualizzazione File 1'!$A:$AR,Y$1,),"")=0,"",IFERROR(VLOOKUP($A:$A,'Matrice Visualizzazione File 1'!$A:$AR,Y$1,),"")) | Z14: =IF(IFERROR(VLOOKUP($A:$A,'Matrice Visualizzazione File 1'!$A:$AR,Z$1,),"")=0,"",IFERROR(VLOOKUP($A:$A,'Matrice Visualizzazione File 1'!$A:$AR,Z$1,),"")) | AA14: =IF(IFERROR(VLOOKUP($A:$A,'Matrice Visualizzazione File 1'!$A:$AR,AA$1,),"")=0,"",IFERROR(VLOOKUP($A:$A,'Matrice Visualizzazione File 1'!$A:$AR,AA$1,),"")) | AB14: =IF(IFERROR(VLOOKUP($A:$A,'Matrice Visualizzazione File 1'!$A:$AR,AB$1,),"")=0,"",IFERROR(VLOOKUP($A:$A,'Matrice Visualizzazione File 1'!$A:$AR,AB$1,),"")) | AC14: =IF(IFERROR(VLOOKUP($A:$A,'Matrice Visualizzazione File 1'!$A:$AR,AC$1,),"")=0,"",IFERROR(VLOOKUP($A:$A,'Matrice Visualizzazione File 1'!$A:$AR,AC$1,),"")) | ... AN14: =IF(IFERROR(VLOOKUP($A:$A,'Matrice Visualizzazione File 1'!$A:$AR,AN$1,),"")=0,"",IFERROR(VLOOKUP($A:$A,'Matrice Visualizzazione File 1'!$A:$AR,AN$1,),""))
A15: =A14+1 -> 10 | B15: =IFERROR(VLOOKUP($A:$A,'Matrice Visualizzazione File 1'!$A:$AR,B$1,),"") -> 0 | C15: =IFERROR(VLOOKUP($A:$A,'Matrice Visualizzazione File 1'!$A:$AR,C$1,),"") -> 0 | D15: =IFERROR(VLOOKUP($A:$A,'Matrice Visualizzazione File 1'!$A:$AR,D$1,),"") -> 0 | E15: =_xlfn.TEXTJOIN("|",TRUE,Tabella_Traslata[[#This Row],[HN]:[CN]]) -> ---|--- | F15: =_xlfn.TEXTJOIN("|",TRUE,Tabella_Traslata[[#This Row],[Sale office 1]:[Sale office 9]]) | G15: =IFERROR(VLOOKUP($A:$A,'Matrice Visualizzazione File 1'!$A:$AR,G$1,),"") -> 0 | H15: =IFERROR(VLOOKUP($A:$A,'Matrice Visualizzazione File 1'!$A:$AR,H$1,),"") -> 0 | I15: =IFERROR(VLOOKUP($A:$A,'Matrice Visualizzazione File 1'!$A:$AR,I$1,),"") -> 0 | J15: =IFERROR(VLOOKUP($A:$A,'Matrice Visualizzazione File 1'!$A:$AR,J$1,),"") -> 0 | K15: =IFERROR(VLOOKUP($A:$A,'Matrice Visualizzazione File 1'!$A:$AR,K$1,),"") -> 0 | L15: =_xlfn.TEXTJOIN("|",TRUE,Tabella_Traslata[[#This Row],[Codice Avviamento 1]:[Codice Avviamento 2]]) | M15: =_xlfn.TEXTJOIN("|",TRUE,Tabella_Traslata[[#This Row],[Accessorio 1]:[Accessorio 5]]) | N15: =IFERROR(VLOOKUP($A:$A,'Matrice Visualizzazione File 1'!$A:$AR,N$1,),"") | O15: =IFERROR(VLOOKUP($A:$A,'Matrice Visualizzazione File 1'!$A:$AR,O$1,),"") | P15: =IFERROR(VLOOKUP($A:$A,'Matrice Visualizzazione File 1'!$A:$AR,P$1,),"") | Q15: =IFERROR(VLOOKUP($A:$A,'Matrice Visualizzazione File 1'!$A:$AR,Q$1,),"") | R15: =IFERROR(VLOOKUP($A:$A,'Matrice Visualizzazione File 1'!$A:$AR,R$1,),"") | S15: =IFERROR(VLOOKUP($A:$A,'Matrice Visualizzazione File 1'!$A:$AR,S$1,),"") -> 0 | T15: =IFERROR(VLOOKUP($A:$A,'Matrice Visualizzazione File 1'!$A:$AR,T$1,),"") | U15: =IFERROR(VLOOKUP($A:$A,'Matrice Visualizzazione File 1'!$A:$AR,U$1,),"") | V15: =IF(IFERROR(VLOOKUP($A:$A,'Matrice Visualizzazione File 1'!$A:$AR,V$1,),"")=0,"",IFERROR(VLOOKUP($A:$A,'Matrice Visualizzazione File 1'!$A:$AR,V$1,),"")) -> --- | W15: =IF(IFERROR(VLOOKUP($A:$A,'Matrice Visualizzazione File 1'!$A:$AR,W$1,),"")=0,"",IFERROR(VLOOKUP($A:$A,'Matrice Visualizzazione File 1'!$A:$AR,W$1,),"")) -> --- | X15: =IF(IFERROR(VLOOKUP($A:$A,'Matrice Visualizzazione File 1'!$A:$AR,X$1,),"")=0,"",IFERROR(VLOOKUP($A:$A,'Matrice Visualizzazione File 1'!$A:$AR,X$1,),"")) | Y15: =IF(IFERROR(VLOOKUP($A:$A,'Matrice Visualizzazione File 1'!$A:$AR,Y$1,),"")=0,"",IFERROR(VLOOKUP($A:$A,'Matrice Visualizzazione File 1'!$A:$AR,Y$1,),"")) | Z15: =IF(IFERROR(VLOOKUP($A:$A,'Matrice Visualizzazione File 1'!$A:$AR,Z$1,),"")=0,"",IFERROR(VLOOKUP($A:$A,'Matrice Visualizzazione File 1'!$A:$AR,Z$1,),"")) | AA15: =IF(IFERROR(VLOOKUP($A:$A,'Matrice Visualizzazione File 1'!$A:$AR,AA$1,),"")=0,"",IFERROR(VLOOKUP($A:$A,'Matrice Visualizzazione File 1'!$A:$AR,AA$1,),"")) | AB15: =IF(IFERROR(VLOOKUP($A:$A,'Matrice Visualizzazione File 1'!$A:$AR,AB$1,),"")=0,"",IFERROR(VLOOKUP($A:$A,'Matrice Visualizzazione File 1'!$A:$AR,AB$1,),"")) | AC15: =IF(IFERROR(VLOOKUP($A:$A,'Matrice Visualizzazione File 1'!$A:$AR,AC$1,),"")=0,"",IFERROR(VLOOKUP($A:$A,'Matrice Visualizzazione File 1'!$A:$AR,AC$1,),"")) | ... AN15: =IF(IFERROR(VLOOKUP($A:$A,'Matrice Visualizzazione File 1'!$A:$AR,AN$1,),"")=0,"",IFERROR(VLOOKUP($A:$A,'Matrice Visualizzazione File 1'!$A:$AR,AN$1,),""))
A16: =A15+1 -> 11 | B16: =IFERROR(VLOOKUP($A:$A,'Matrice Visualizzazione File 1'!$A:$AR,B$1,),"") -> AACCP0E00 | C16: =IFERROR(VLOOKUP($A:$A,'Matrice Visualizzazione File 1'!$A:$AR,C$1,),"") -> AS25PCHHRA-NR | D16: =IFERROR(VLOOKUP($A:$A,'Matrice Visualizzazione File 1'!$A:$AR,D$1,),"") -> IU | E16: =_xlfn.TEXTJOIN("|",TRUE,Tabella_Traslata[[#This Row],[HN]:[CN]]) -> RN | F16: =_xlfn.TEXTJOIN("|",TRUE,Tabella_Traslata[[#This Row],[Sale office 1]:[Sale office 9]]) -> AGIR|ASI0 | G16: =IFERROR(VLOOKUP($A:$A,'Matrice Visualizzazione File 1'!$A:$AR,G$1,),"") -> Yes | H16: =IFERROR(VLOOKUP($A:$A,'Matrice Visualizzazione File 1'!$A:$AR,H$1,),"") -> Pearl Nordic | I16: =IFERROR(VLOOKUP($A:$A,'Matrice Visualizzazione File 1'!$A:$AR,I$1,),"") -> 0 | J16: =IFERROR(VLOOKUP($A:$A,'Matrice Visualizzazione File 1'!$A:$AR,J$1,),"") -> 5 | K16: =IFERROR(VLOOKUP($A:$A,'Matrice Visualizzazione File 1'!$A:$AR,K$1,),"") -> Catologue | L16: =_xlfn.TEXTJOIN("|",TRUE,Tabella_Traslata[[#This Row],[Codice Avviamento 1]:[Codice Avviamento 2]]) | M16: =_xlfn.TEXTJOIN("|",TRUE,Tabella_Traslata[[#This Row],[Accessorio 1]:[Accessorio 5]]) | N16: =IFERROR(VLOOKUP($A:$A,'Matrice Visualizzazione File 1'!$A:$AR,N$1,),"") | O16: =IFERROR(VLOOKUP($A:$A,'Matrice Visualizzazione File 1'!$A:$AR,O$1,),"") | P16: =IFERROR(VLOOKUP($A:$A,'Matrice Visualizzazione File 1'!$A:$AR,P$1,),"") | Q16: =IFERROR(VLOOKUP($A:$A,'Matrice Visualizzazione File 1'!$A:$AR,Q$1,),"") | R16: =IFERROR(VLOOKUP($A:$A,'Matrice Visualizzazione File 1'!$A:$AR,R$1,),"") | S16: =IFERROR(VLOOKUP($A:$A,'Matrice Visualizzazione File 1'!$A:$AR,S$1,),"") -> 0 | T16: =IFERROR(VLOOKUP($A:$A,'Matrice Visualizzazione File 1'!$A:$AR,T$1,),"") | U16: =IFERROR(VLOOKUP($A:$A,'Matrice Visualizzazione File 1'!$A:$AR,U$1,),"") | V16: =IF(IFERROR(VLOOKUP($A:$A,'Matrice Visualizzazione File 1'!$A:$AR,V$1,),"")=0,"",IFERROR(VLOOKUP($A:$A,'Matrice Visualizzazione File 1'!$A:$AR,V$1,),"")) | W16: =IF(IFERROR(VLOOKUP($A:$A,'Matrice Visualizzazione File 1'!$A:$AR,W$1,),"")=0,"",IFERROR(VLOOKUP($A:$A,'Matrice Visualizzazione File 1'!$A:$AR,W$1,),"")) -> RN | X16: =IF(IFERROR(VLOOKUP($A:$A,'Matrice Visualizzazione File 1'!$A:$AR,X$1,),"")=0,"",IFERROR(VLOOKUP($A:$A,'Matrice Visualizzazione File 1'!$A:$AR,X$1,),"")) | Y16: =IF(IFERROR(VLOOKUP($A:$A,'Matrice Visualizzazione File 1'!$A:$AR,Y$1,),"")=0,"",IFERROR(VLOOKUP($A:$A,'Matrice Visualizzazione File 1'!$A:$AR,Y$1,),"")) | Z16: =IF(IFERROR(VLOOKUP($A:$A,'Matrice Visualizzazione File 1'!$A:$AR,Z$1,),"")=0,"",IFERROR(VLOOKUP($A:$A,'Matrice Visualizzazione File 1'!$A:$AR,Z$1,),"")) | AA16: =IF(IFERROR(VLOOKUP($A:$A,'Matrice Visualizzazione File 1'!$A:$AR,AA$1,),"")=0,"",IFERROR(VLOOKUP($A:$A,'Matrice Visualizzazione File 1'!$A:$AR,AA$1,),"")) | AB16: =IF(IFERROR(VLOOKUP($A:$A,'Matrice Visualizzazione File 1'!$A:$AR,AB$1,),"")=0,"",IFERROR(VLOOKUP($A:$A,'Matrice Visualizzazione File 1'!$A:$AR,AB$1,),"")) | AC16: =IF(IFERROR(VLOOKUP($A:$A,'Matrice Visualizzazione File 1'!$A:$AR,AC$1,),"")=0,"",IFERROR(VLOOKUP($A:$A,'Matrice Visualizzazione File 1'!$A:$AR,AC$1,),"")) | ... AN16: =IF(IFERROR(VLOOKUP($A:$A,'Matrice Visualizzazione File 1'!$A:$AR,AN$1,),"")=0,"",IFERROR(VLOOKUP($A:$A,'Matrice Visualizzazione File 1'!$A:$AR,AN$1,),""))
